2021-03-09 07:03:34,562 ERROR: Exception on /register [POST] [in C:\Users\Hippi\AppData\Local\Programs\Python\Python38-32\lib\site-packages\flask\app.py:1891]
Traceback (most recent call last):
  File "C:\Users\Hippi\AppData\Local\Programs\Python\Python38-32\lib\site-packages\sqlalchemy\engine\base.py", line 1276, in _execute_context
    self.dialect.do_execute(
  File "C:\Users\Hippi\AppData\Local\Programs\Python\Python38-32\lib\site-packages\sqlalchemy\engine\default.py", line 608, in do_execute
    cursor.execute(statement, parameters)
sqlite3.OperationalError: no such table: user

The above exception was the direct cause of the following exception:

Traceback (most recent call last):
  File "C:\Users\Hippi\AppData\Local\Programs\Python\Python38-32\lib\site-packages\flask\app.py", line 2447, in wsgi_app
    response = self.full_dispatch_request()
  File "C:\Users\Hippi\AppData\Local\Programs\Python\Python38-32\lib\site-packages\flask\app.py", line 1952, in full_dispatch_request
    rv = self.handle_user_exception(e)
  File "C:\Users\Hippi\AppData\Local\Programs\Python\Python38-32\lib\site-packages\flask\app.py", line 1821, in handle_user_exception
    reraise(exc_type, exc_value, tb)
  File "C:\Users\Hippi\AppData\Local\Programs\Python\Python38-32\lib\site-packages\flask\_compat.py", line 39, in reraise
    raise value
  File "C:\Users\Hippi\AppData\Local\Programs\Python\Python38-32\lib\site-packages\flask\app.py", line 1950, in full_dispatch_request
    rv = self.dispatch_request()
  File "C:\Users\Hippi\AppData\Local\Programs\Python\Python38-32\lib\site-packages\flask\app.py", line 1936, in dispatch_request
    return self.view_functions[rule.endpoint](**req.view_args)
  File "D:\Users\Hippi\Desktop\UvACourses\DSCS\meal-app\app\routes.py", line 170, in register
    if form.validate_on_submit():
  File "C:\Users\Hippi\AppData\Local\Programs\Python\Python38-32\lib\site-packages\flask_wtf\form.py", line 100, in validate_on_submit
    return self.is_submitted() and self.validate()
  File "C:\Users\Hippi\AppData\Local\Programs\Python\Python38-32\lib\site-packages\wtforms\form.py", line 318, in validate
    return super(Form, self).validate(extra)
  File "C:\Users\Hippi\AppData\Local\Programs\Python\Python38-32\lib\site-packages\wtforms\form.py", line 150, in validate
    if not field.validate(self, extra):
  File "C:\Users\Hippi\AppData\Local\Programs\Python\Python38-32\lib\site-packages\wtforms\fields\core.py", line 226, in validate
    stop_validation = self._run_validation_chain(form, chain)
  File "C:\Users\Hippi\AppData\Local\Programs\Python\Python38-32\lib\site-packages\wtforms\fields\core.py", line 246, in _run_validation_chain
    validator(form, self)
  File "D:\Users\Hippi\Desktop\UvACourses\DSCS\meal-app\app\forms.py", line 84, in validate_username
    user = User.query.filter_by(username=username.data).first()
  File "C:\Users\Hippi\AppData\Local\Programs\Python\Python38-32\lib\site-packages\sqlalchemy\orm\query.py", line 3429, in first
    ret = list(self[0:1])
  File "C:\Users\Hippi\AppData\Local\Programs\Python\Python38-32\lib\site-packages\sqlalchemy\orm\query.py", line 3203, in __getitem__
    return list(res)
  File "C:\Users\Hippi\AppData\Local\Programs\Python\Python38-32\lib\site-packages\sqlalchemy\orm\query.py", line 3535, in __iter__
    return self._execute_and_instances(context)
  File "C:\Users\Hippi\AppData\Local\Programs\Python\Python38-32\lib\site-packages\sqlalchemy\orm\query.py", line 3560, in _execute_and_instances
    result = conn.execute(querycontext.statement, self._params)
  File "C:\Users\Hippi\AppData\Local\Programs\Python\Python38-32\lib\site-packages\sqlalchemy\engine\base.py", line 1011, in execute
    return meth(self, multiparams, params)
  File "C:\Users\Hippi\AppData\Local\Programs\Python\Python38-32\lib\site-packages\sqlalchemy\sql\elements.py", line 298, in _execute_on_connection
    return connection._execute_clauseelement(self, multiparams, params)
  File "C:\Users\Hippi\AppData\Local\Programs\Python\Python38-32\lib\site-packages\sqlalchemy\engine\base.py", line 1124, in _execute_clauseelement
    ret = self._execute_context(
  File "C:\Users\Hippi\AppData\Local\Programs\Python\Python38-32\lib\site-packages\sqlalchemy\engine\base.py", line 1316, in _execute_context
    self._handle_dbapi_exception(
  File "C:\Users\Hippi\AppData\Local\Programs\Python\Python38-32\lib\site-packages\sqlalchemy\engine\base.py", line 1510, in _handle_dbapi_exception
    util.raise_(
  File "C:\Users\Hippi\AppData\Local\Programs\Python\Python38-32\lib\site-packages\sqlalchemy\util\compat.py", line 182, in raise_
    raise exception
  File "C:\Users\Hippi\AppData\Local\Programs\Python\Python38-32\lib\site-packages\sqlalchemy\engine\base.py", line 1276, in _execute_context
    self.dialect.do_execute(
  File "C:\Users\Hippi\AppData\Local\Programs\Python\Python38-32\lib\site-packages\sqlalchemy\engine\default.py", line 608, in do_execute
    cursor.execute(statement, parameters)
sqlalchemy.exc.OperationalError: (sqlite3.OperationalError) no such table: user
[SQL: SELECT user.id AS user_id, user.username AS user_username, user.email AS user_email, user.password_hash AS user_password_hash, user.about_me AS user_about_me, user.last_seen AS user_last_seen, user.first_name AS user_first_name, user.last_name AS user_last_name, user.address AS user_address, user.postal_code AS user_postal_code, user.state_province AS user_state_province, user.country AS user_country, user.interest AS user_interest, user.lat AS user_lat, user.lng AS user_lng, user.last_message_read_time AS user_last_message_read_time 
FROM user 
WHERE user.username = ?
 LIMIT ? OFFSET ?]
[parameters: ('mat', 1, 0)]
(Background on this error at: http://sqlalche.me/e/13/e3q8)
2021-03-09 07:03:58,664 INFO: App startup [in D:\Users\Hippi\Desktop\UvACourses\DSCS\meal-app\app\__init__.py:65]
2021-03-09 07:04:17,392 INFO: App startup [in D:\Users\Hippi\Desktop\UvACourses\DSCS\meal-app\app\__init__.py:65]
2021-03-09 07:05:27,572 INFO: App startup [in D:\Users\Hippi\Desktop\UvACourses\DSCS\meal-app\app\__init__.py:65]
2021-03-09 07:05:39,997 INFO: App startup [in D:\Users\Hippi\Desktop\UvACourses\DSCS\meal-app\app\__init__.py:65]
2021-03-09 07:09:56,683 INFO: App startup [in D:\Users\Hippi\Desktop\UvACourses\DSCS\meal-app\app\__init__.py:65]
2021-03-09 07:22:56,743 INFO: App startup [in D:\Users\Hippi\Desktop\UvACourses\DSCS\meal-app\app\__init__.py:65]
2021-03-09 07:23:50,177 INFO: App startup [in D:\Users\Hippi\Desktop\UvACourses\DSCS\meal-app\app\__init__.py:65]
2021-03-09 07:25:49,562 INFO: App startup [in D:\Users\Hippi\Desktop\UvACourses\DSCS\meal-app\app\__init__.py:65]
2021-03-09 07:26:36,091 INFO: App startup [in D:\Users\Hippi\Desktop\UvACourses\DSCS\meal-app\app\__init__.py:65]
2021-03-09 07:26:59,594 INFO: App startup [in D:\Users\Hippi\Desktop\UvACourses\DSCS\meal-app\app\__init__.py:65]
2021-03-09 07:32:32,263 INFO: App startup [in D:\Users\Hippi\Desktop\UvACourses\DSCS\meal-app\app\__init__.py:65]
2021-03-09 07:33:09,139 INFO: App startup [in D:\Users\Hippi\Desktop\UvACourses\DSCS\meal-app\app\__init__.py:65]
2021-03-09 07:33:21,226 INFO: App startup [in D:\Users\Hippi\Desktop\UvACourses\DSCS\meal-app\app\__init__.py:65]
2021-03-09 07:34:34,810 INFO: App startup [in D:\Users\Hippi\Desktop\UvACourses\DSCS\meal-app\app\__init__.py:65]
2021-03-09 07:35:38,964 INFO: App startup [in D:\Users\Hippi\Desktop\UvACourses\DSCS\meal-app\app\__init__.py:65]
2021-03-09 07:35:58,640 INFO: App startup [in D:\Users\Hippi\Desktop\UvACourses\DSCS\meal-app\app\__init__.py:65]
